Workbook

Sheet Painel
B1: PLANO PROPULSE · Painel de cobranças
B2: ="Atualizado em "&TEXT(TODAY(),"dd/mm/yyyy")&" · abra todo dia e cobre quem está em vermelho" -> Atualizado em 09/10/2026 · abra todo dia e cobre quem está em vermelho
B4: Artistas ativos | C4: Tarefas abertas | D4: 🔴 Atrasadas – cobrar | E4: 🟠 Vencem em 3 dias | F4: ✅ Concluídas | G4: % concluído
B5: =COUNTIFS(Artistas!$F$5:$F$104,"Ativo") -> 3 | C5: =COUNTIFS(Lançamentos!$A$2:$A$401,"<>",Lançamentos!$G$2:$G$401,"<>Concluído") -> 10 | D5: =COUNTIFS(Lançamentos!$A$2:$A$401,"<>",Lançamentos!$G$2:$G$401,"<>Concluído",Lançamentos!$F$2:$F$401,"<"&TODAY()) -> 2 | E5: =COUNTIFS(Lançamentos!$A$2:$A$401,"<>",Lançamentos!$G$2:$G$401,"<>Concluído",Lançamentos!$F$2:$F$401,">="&TODAY(),Lançamentos!$F$2:$F$401,"<="&TODAY()+3) -> 4 | F5: =COUNTIFS(Lançamentos!$A$2:$A$401,"<>",Lançamentos!$G$2:$G$401,"Concluído") -> 5 | G5: =IFERROR(F5/COUNTIFS(Lançamentos!$A$2:$A$401,"<>"),0) -> 0.33333333
B7: 📣 QUEM COBRAR (atrasadas e vencendo em até 3 dias, da mais urgente para a menos)
B8: Responsável | C8: Artista | D8: Etapa | E8: Lançamento | F8: Prazo | G8: Situação
B9: =IF($K9="",IF(AND(1=1,COLUMN()=2),"Nada para cobrar hoje 🎉",""),INDEX(Lançamentos!$E:$E,$K9)) -> Bruno Lima | C9: =IF($K9="",IF(AND(1=1,COLUMN()=2),"Nada para cobrar hoje 🎉",""),INDEX(Lançamentos!$A:$A,$K9)) -> Luna Ribeiro | D9: =IF($K9="",IF(AND(1=1,COLUMN()=2),"Nada para cobrar hoje 🎉",""),INDEX(Lançamentos!$D:$D,$K9)) -> Pitch editorial Spotify | E9: =IF($K9="",IF(AND(1=1,COLUMN()=2),"Nada para cobrar hoje 🎉",""),INDEX(Lançamentos!$B:$B,$K9)) -> Maré Alta | F9: =IF($K9="",IF(AND(1=1,COLUMN()=2),"Nada para cobrar hoje 🎉",""),INDEX(Lançamentos!$F:$F,$K9)) -> 46301 | G9: =IF($K9="",IF(AND(1=1,COLUMN()=2),"Nada para cobrar hoje 🎉",""),INDEX(Lançamentos!$I:$I,$K9)) -> 🔴 COBRAR · 3 dia(s) atrasado | K9: =IFERROR(MATCH(SMALL(Lançamentos!$L$2:$L$401,1),Lançamentos!$L$2:$L$401,0)+1,"") -> 5
B10: =IF($K10="",IF(AND(2=1,COLUMN()=2),"Nada para cobrar hoje 🎉",""),INDEX(Lançamentos!$E:$E,$K10)) -> Carla Mendes | C10: =IF($K10="",IF(AND(2=1,COLUMN()=2),"Nada para cobrar hoje 🎉",""),INDEX(Lançamentos!$A:$A,$K10)) -> Luna Ribeiro | D10: =IF($K10="",IF(AND(2=1,COLUMN()=2),"Nada para cobrar hoje 🎉",""),INDEX(Lançamentos!$D:$D,$K10)) -> Pré-save | E10: =IF($K10="",IF(AND(2=1,COLUMN()=2),"Nada para cobrar hoje 🎉",""),INDEX(Lançamentos!$B:$B,$K10)) -> Maré Alta | F10: =IF($K10="",IF(AND(2=1,COLUMN()=2),"Nada para cobrar hoje 🎉",""),INDEX(Lançamentos!$F:$F,$K10)) -> 46301 | G10: =IF($K10="",IF(AND(2=1,COLUMN()=2),"Nada para cobrar hoje 🎉",""),INDEX(Lançamentos!$I:$I,$K10)) -> 🔴 COBRAR · 3 dia(s) atrasado | K10: =IFERROR(MATCH(SMALL(Lançamentos!$L$2:$L$401,2),Lançamentos!$L$2:$L$401,0)+1,"") -> 6
B11: =IF($K11="",IF(AND(3=1,COLUMN()=2),"Nada para cobrar hoje 🎉",""),INDEX(Lançamentos!$E:$E,$K11)) -> Elisa Rocha | C11: =IF($K11="",IF(AND(3=1,COLUMN()=2),"Nada para cobrar hoje 🎉",""),INDEX(Lançamentos!$A:$A,$K11)) -> Luna Ribeiro | D11: =IF($K11="",IF(AND(3=1,COLUMN()=2),"Nada para cobrar hoje 🎉",""),INDEX(Lançamentos!$D:$D,$K11)) -> Release / assessoria | E11: =IF($K11="",IF(AND(3=1,COLUMN()=2),"Nada para cobrar hoje 🎉",""),INDEX(Lançamentos!$B:$B,$K11)) -> Maré Alta | F11: =IF($K11="",IF(AND(3=1,COLUMN()=2),"Nada para cobrar hoje 🎉",""),INDEX(Lançamentos!$F:$F,$K11)) -> 46304 | G11: =IF($K11="",IF(AND(3=1,COLUMN()=2),"Nada para cobrar hoje 🎉",""),INDEX(Lançamentos!$I:$I,$K11)) -> 🟠 Vence HOJE | K11: =IFERROR(MATCH(SMALL(Lançamentos!$L$2:$L$401,3),Lançamentos!$L$2:$L$401,0)+1,"") -> 7
B12: =IF($K12="",IF(AND(4=1,COLUMN()=2),"Nada para cobrar hoje 🎉",""),INDEX(Lançamentos!$E:$E,$K12)) -> Carla Mendes | C12: =IF($K12="",IF(AND(4=1,COLUMN()=2),"Nada para cobrar hoje 🎉",""),INDEX(Lançamentos!$A:$A,$K12)) -> Luna Ribeiro | D12: =IF($K12="",IF(AND(4=1,COLUMN()=2),"Nada para cobrar hoje 🎉",""),INDEX(Lançamentos!$D:$D,$K12)) -> Conteúdo para redes (teasers) | E12: =IF($K12="",IF(AND(4=1,COLUMN()=2),"Nada para cobrar hoje 🎉",""),INDEX(Lançamentos!$B:$B,$K12)) -> Maré Alta | F12: =IF($K12="",IF(AND(4=1,COLUMN()=2),"Nada para cobrar hoje 🎉",""),INDEX(Lançamentos!$F:$F,$K12)) -> 46304 | G12: =IF($K12="",IF(AND(4=1,COLUMN()=2),"Nada para cobrar hoje 🎉",""),INDEX(Lançamentos!$I:$I,$K12)) -> 🟠 Vence HOJE | K12: =IFERROR(MATCH(SMALL(Lançamentos!$L$2:$L$401,4),Lançamentos!$L$2:$L$401,0)+1,"") -> 8
B13: =IF($K13="",IF(AND(5=1,COLUMN()=2),"Nada para cobrar hoje 🎉",""),INDEX(Lançamentos!$E:$E,$K13)) -> Ana Souza | C13: =IF($K13="",IF(AND(5=1,COLUMN()=2),"Nada para cobrar hoje 🎉",""),INDEX(Lançamentos!$A:$A,$K13)) -> MC Taveira | D13: =IF($K13="",IF(AND(5=1,COLUMN()=2),"Nada para cobrar hoje 🎉",""),INDEX(Lançamentos!$D:$D,$K13)) -> Capa / arte | E13: =IF($K13="",IF(AND(5=1,COLUMN()=2),"Nada para cobrar hoje 🎉",""),INDEX(Lançamentos!$B:$B,$K13)) -> Favela Sonha | F13: =IF($K13="",IF(AND(5=1,COLUMN()=2),"Nada para cobrar hoje 🎉",""),INDEX(Lançamentos!$F:$F,$K13)) -> 46304 | G13: =IF($K13="",IF(AND(5=1,COLUMN()=2),"Nada para cobrar hoje 🎉",""),INDEX(Lançamentos!$I:$I,$K13)) -> 🟠 Vence HOJE | K13: =IFERROR(MATCH(SMALL(Lançamentos!$L$2:$L$401,5),Lançamentos!$L$2:$L$401,0)+1,"") -> 11
B14: =IF($K14="",IF(AND(6=1,COLUMN()=2),"Nada para cobrar hoje 🎉",""),INDEX(Lançamentos!$E:$E,$K14)) -> Diego Alves | C14: =IF($K14="",IF(AND(6=1,COLUMN()=2),"Nada para cobrar hoje 🎉",""),INDEX(Lançamentos!$A:$A,$K14)) -> Banda Aurora | D14: =IF($K14="",IF(AND(6=1,COLUMN()=2),"Nada para cobrar hoje 🎉",""),INDEX(Lançamentos!$D:$D,$K14)) -> Relatório pós-lançamento | E14: =IF($K14="",IF(AND(6=1,COLUMN()=2),"Nada para cobrar hoje 🎉",""),INDEX(Lançamentos!$B:$B,$K14)) -> Céu de Outubro | F14: =IF($K14="",IF(AND(6=1,COLUMN()=2),"Nada para cobrar hoje 🎉",""),INDEX(Lançamentos!$F:$F,$K14)) -> 46304 | G14: =IF($K14="",IF(AND(6=1,COLUMN()=2),"Nada para cobrar hoje 🎉",""),INDEX(Lançamentos!$I:$I,$K14)) -> 🟠 Vence HOJE | K14: =IFERROR(MATCH(SMALL(Lançamentos!$L$2:$L$401,6),Lançamentos!$L$2:$L$401,0)+1,"") -> 16
B15: =IF($K15="",IF(AND(7=1,COLUMN()=2),"Nada para cobrar hoje 🎉",""),INDEX(Lançamentos!$E:$E,$K15)) | C15: =IF($K15="",IF(AND(7=1,COLUMN()=2),"Nada para cobrar hoje 🎉",""),INDEX(Lançamentos!$A:$A,$K15)) | D15: =IF($K15="",IF(AND(7=1,COLUMN()=2),"Nada para cobrar hoje 🎉",""),INDEX(Lançamentos!$D:$D,$K15)) | E15: =IF($K15="",IF(AND(7=1,COLUMN()=2),"Nada para cobrar hoje 🎉",""),INDEX(Lançamentos!$B:$B,$K15)) | F15: =IF($K15="",IF(AND(7=1,COLUMN()=2),"Nada para cobrar hoje 🎉",""),INDEX(Lançamentos!$F:$F,$K15)) | G15: =IF($K15="",IF(AND(7=1,COLUMN()=2),"Nada para cobrar hoje 🎉",""),INDEX(Lançamentos!$I:$I,$K15)) | K15: =IFERROR(MATCH(SMALL(Lançamentos!$L$2:$L$401,7),Lançamentos!$L$2:$L$401,0)+1,"")
B16: =IF($K16="",IF(AND(8=1,COLUMN()=2),"Nada para cobrar hoje 🎉",""),INDEX(Lançamentos!$E:$E,$K16)) | C16: =IF($K16="",IF(AND(8=1,COLUMN()=2),"Nada para cobrar hoje 🎉",""),INDEX(Lançamentos!$A:$A,$K16)) | D16: =IF($K16="",IF(AND(8=1,COLUMN()=2),"Nada para cobrar hoje 🎉",""),INDEX(Lançamentos!$D:$D,$K16)) | E16: =IF($K16="",IF(AND(8=1,COLUMN()=2),"Nada para cobrar hoje 🎉",""),INDEX(Lançamentos!$B:$B,$K16)) | F16: =IF($K16="",IF(AND(8=1,COLUMN()=2),"Nada para cobrar hoje 🎉",""),INDEX(Lançamentos!$F:$F,$K16)) | G16: =IF($K16="",IF(AND(8=1,COLUMN()=2),"Nada para cobrar hoje 🎉",""),INDEX(Lançamentos!$I:$I,$K16)) | K16: =IFERROR(MATCH(SMALL(Lançamentos!$L$2:$L$401,8),Lançamentos!$L$2:$L$401,0)+1,"")
B17: =IF($K17="",IF(AND(9=1,COLUMN()=2),"Nada para cobrar hoje 🎉",""),INDEX(Lançamentos!$E:$E,$K17)) | C17: =IF($K17="",IF(AND(9=1,COLUMN()=2),"Nada para cobrar hoje 🎉",""),INDEX(Lançamentos!$A:$A,$K17)) | D17: =IF($K17="",IF(AND(9=1,COLUMN()=2),"Nada para cobrar hoje 🎉",""),INDEX(Lançamentos!$D:$D,$K17)) | E17: =IF($K17="",IF(AND(9=1,COLUMN()=2),"Nada para cobrar hoje 🎉",""),INDEX(Lançamentos!$B:$B,$K17)) | F17: =IF($K17="",IF(AND(9=1,COLUMN()=2),"Nada para cobrar hoje 🎉",""),INDEX(Lançamentos!$F:$F,$K17)) | G17: =IF($K17="",IF(AND(9=1,COLUMN()=2),"Nada para cobrar hoje 🎉",""),INDEX(Lançamentos!$I:$I,$K17)) | K17: =IFERROR(MATCH(SMALL(Lançamentos!$L$2:$L$401,9),Lançamentos!$L$2:$L$401,0)+1,"")
B18: =IF($K18="",IF(AND(10=1,COLUMN()=2),"Nada para cobrar hoje 🎉",""),INDEX(Lançamentos!$E:$E,$K18)) | C18: =IF($K18="",IF(AND(10=1,COLUMN()=2),"Nada para cobrar hoje 🎉",""),INDEX(Lançamentos!$A:$A,$K18)) | D18: =IF($K18="",IF(AND(10=1,COLUMN()=2),"Nada para cobrar hoje 🎉",""),INDEX(Lançamentos!$D:$D,$K18)) | E18: =IF($K18="",IF(AND(10=1,COLUMN()=2),"Nada para cobrar hoje 🎉",""),INDEX(Lançamentos!$B:$B,$K18)) | F18: =IF($K18="",IF(AND(10=1,COLUMN()=2),"Nada para cobrar hoje 🎉",""),INDEX(Lançamentos!$F:$F,$K18)) | G18: =IF($K18="",IF(AND(10=1,COLUMN()=2),"Nada para cobrar hoje 🎉",""),INDEX(Lançamentos!$I:$I,$K18)) | K18: =IFERROR(MATCH(SMALL(Lançamentos!$L$2:$L$401,10),Lançamentos!$L$2:$L$401,0)+1,"")
B19: =IF($K19="",IF(AND(11=1,COLUMN()=2),"Nada para cobrar hoje 🎉",""),INDEX(Lançamentos!$E:$E,$K19)) | C19: =IF($K19="",IF(AND(11=1,COLUMN()=2),"Nada para cobrar hoje 🎉",""),INDEX(Lançamentos!$A:$A,$K19)) | D19: =IF($K19="",IF(AND(11=1,COLUMN()=2),"Nada para cobrar hoje 🎉",""),INDEX(Lançamentos!$D:$D,$K19)) | E19: =IF($K19="",IF(AND(11=1,COLUMN()=2),"Nada para cobrar hoje 🎉",""),INDEX(Lançamentos!$B:$B,$K19)) | F19: =IF($K19="",IF(AND(11=1,COLUMN()=2),"Nada para cobrar hoje 🎉",""),INDEX(Lançamentos!$F:$F,$K19)) | G19: =IF($K19="",IF(AND(11=1,COLUMN()=2),"Nada para cobrar hoje 🎉",""),INDEX(Lançamentos!$I:$I,$K19)) | K19: =IFERROR(MATCH(SMALL(Lançamentos!$L$2:$L$401,11),Lançamentos!$L$2:$L$401,0)+1,"")
B20: =IF($K20="",IF(AND(12=1,COLUMN()=2),"Nada para cobrar hoje 🎉",""),INDEX(Lançamentos!$E:$E,$K20)) | C20: =IF($K20="",IF(AND(12=1,COLUMN()=2),"Nada para cobrar hoje 🎉",""),INDEX(Lançamentos!$A:$A,$K20)) | D20: =IF($K20="",IF(AND(12=1,COLUMN()=2),"Nada para cobrar hoje 🎉",""),INDEX(Lançamentos!$D:$D,$K20)) | E20: =IF($K20="",IF(AND(12=1,COLUMN()=2),"Nada para cobrar hoje 🎉",""),INDEX(Lançamentos!$B:$B,$K20)) | F20: =IF($K20="",IF(AND(12=1,COLUMN()=2),"Nada para cobrar hoje 🎉",""),INDEX(Lançamentos!$F:$F,$K20)) | G20: =IF($K20="",IF(AND(12=1,COLUMN()=2),"Nada para cobrar hoje 🎉",""),INDEX(Lançamentos!$I:$I,$K20)) | K20: =IFERROR(MATCH(SMALL(Lançamentos!$L$2:$L$401,12),Lançamentos!$L$2:$L$401,0)+1,"")
B21: =IF($K21="",IF(AND(13=1,COLUMN()=2),"Nada para cobrar hoje 🎉",""),INDEX(Lançamentos!$E:$E,$K21)) | C21: =IF($K21="",IF(AND(13=1,COLUMN()=2),"Nada para cobrar hoje 🎉",""),INDEX(Lançamentos!$A:$A,$K21)) | D21: =IF($K21="",IF(AND(13=1,COLUMN()=2),"Nada para cobrar hoje 🎉",""),INDEX(Lançamentos!$D:$D,$K21)) | E21: =IF($K21="",IF(AND(13=1,COLUMN()=2),"Nada para cobrar hoje 🎉",""),INDEX(Lançamentos!$B:$B,$K21)) | F21: =IF($K21="",IF(AND(13=1,COLUMN()=2),"Nada para cobrar hoje 🎉",""),INDEX(Lançamentos!$F:$F,$K21)) | G21: =IF($K21="",IF(AND(13=1,COLUMN()=2),"Nada para cobrar hoje 🎉",""),INDEX(Lançamentos!$I:$I,$K21)) | K21: =IFERROR(MATCH(SMALL(Lançamentos!$L$2:$L$401,13),Lançamentos!$L$2:$L$401,0)+1,"")
B22: =IF($K22="",IF(AND(14=1,COLUMN()=2),"Nada para cobrar hoje 🎉",""),INDEX(Lançamentos!$E:$E,$K22)) | C22: =IF($K22="",IF(AND(14=1,COLUMN()=2),"Nada para cobrar hoje 🎉",""),INDEX(Lançamentos!$A:$A,$K22)) | D22: =IF($K22="",IF(AND(14=1,COLUMN()=2),"Nada para cobrar hoje 🎉",""),INDEX(Lançamentos!$D:$D,$K22)) | E22: =IF($K22="",IF(AND(14=1,COLUMN()=2),"Nada para cobrar hoje 🎉",""),INDEX(Lançamentos!$B:$B,$K22)) | F22: =IF($K22="",IF(AND(14=1,COLUMN()=2),"Nada para cobrar hoje 🎉",""),INDEX(Lançamentos!$F:$F,$K22)) | G22: =IF($K22="",IF(AND(14=1,COLUMN()=2),"Nada para cobrar hoje 🎉",""),INDEX(Lançamentos!$I:$I,$K22)) | K22: =IFERROR(MATCH(SMALL(Lançamentos!$L$2:$L$401,14),Lançamentos!$L$2:$L$401,0)+1,"")
B23: =IF($K23="",IF(AND(15=1,COLUMN()=2),"Nada para cobrar hoje 🎉",""),INDEX(Lançamentos!$E:$E,$K23)) | C23: =IF($K23="",IF(AND(15=1,COLUMN()=2),"Nada para cobrar hoje 🎉",""),INDEX(Lançamentos!$A:$A,$K23)) | D23: =IF($K23="",IF(AND(15=1,COLUMN()=2),"Nada para cobrar hoje 🎉",""),INDEX(Lançamentos!$D:$D,$K23)) | E23: =IF($K23="",IF(AND(15=1,COLUMN()=2),"Nada para cobrar hoje 🎉",""),INDEX(Lançamentos!$B:$B,$K23)) | F23: =IF($K23="",IF(AND(15=1,COLUMN()=2),"Nada para cobrar hoje 🎉",""),INDEX(Lançamentos!$F:$F,$K23)) | G23: =IF($K23="",IF(AND(15=1,COLUMN()=2),"Nada para cobrar hoje 🎉",""),INDEX(Lançamentos!$I:$I,$K23)) | K23: =IFERROR(MATCH(SMALL(Lançamentos!$L$2:$L$401,15),Lançamentos!$L$2:$L$401,0)+1,"")
B24: Mostra as 15 mais urgentes. Lista completa: aba Lançamentos → filtre a coluna Alerta.
B26: 👥 POR RESPONSÁVEL
B27: Responsável | C27: Abertas | D27: 🔴 Atrasadas | E27: 🟠 Vencem ≤3 dias | F27: Situação
B28: =IF(Responsáveis!$A$5="","",Responsáveis!A5) -> Ana Souza | C28: =IF(Responsáveis!$A$5="","",Responsáveis!E5) -> 2 | D28: =IF(Responsáveis!$A$5="","",Responsáveis!F5) -> 0 | E28: =IF(Responsáveis!$A$5="","",Responsáveis!G5) -> 1 | F28: =IF(Responsáveis!$A$5="","",Responsáveis!H5) -> 🟠 Lembrar esta semana
B29: =IF(Responsáveis!$A$6="","",Responsáveis!A6) -> Bruno Lima | C29: =IF(Responsáveis!$A$6="","",Responsáveis!E6) -> 3 | D29: =IF(Responsáveis!$A$6="","",Responsáveis!F6) -> 1 | E29: =IF(Responsáveis!$A$6="","",Responsáveis!G6) -> 0 | F29: =IF(Responsáveis!$A$6="","",Responsáveis!H6) -> 🔴 COBRAR hoje
B30: =IF(Responsáveis!$A$7="","",Responsáveis!A7) -> Carla Mendes | C30: =IF(Responsáveis!$A$7="","",Responsáveis!E7) -> 2 | D30: =IF(Responsáveis!$A$7="","",Responsáveis!F7) -> 1 | E30: =IF(Responsáveis!$A$7="","",Responsáveis!G7) -> 1 | F30: =IF(Responsáveis!$A$7="","",Responsáveis!H7) -> 🔴 COBRAR hoje
B31: =IF(Responsáveis!$A$8="","",Responsáveis!A8) -> Diego Alves | C31: =IF(Responsáveis!$A$8="","",Responsáveis!E8) -> 2 | D31: =IF(Responsáveis!$A$8="","",Responsáveis!F8) -> 0 | E31: =IF(Responsáveis!$A$8="","",Responsáveis!G8) -> 1 | F31: =IF(Responsáveis!$A$8="","",Responsáveis!H8) -> 🟠 Lembrar esta semana
B32: =IF(Responsáveis!$A$9="","",Responsáveis!A9) -> Elisa Rocha | C32: =IF(Responsáveis!$A$9="","",Responsáveis!E9) -> 1 | D32: =IF(Responsáveis!$A$9="","",Responsáveis!F9) -> 0 | E32: =IF(Responsáveis!$A$9="","",Responsáveis!G9) -> 1 | F32: =IF(Responsáveis!$A$9="","",Responsáveis!H9) -> 🟠 Lembrar esta semana
B33: =IF(Responsáveis!$A$10="","",Responsáveis!A10) | C33: =IF(Responsáveis!$A$10="","",Responsáveis!E10) | D33: =IF(Responsáveis!$A$10="","",Responsáveis!F10) | E33: =IF(Responsáveis!$A$10="","",Responsáveis!G10) | F33: =IF(Responsáveis!$A$10="","",Responsáveis!H10)
B34: =IF(Responsáveis!$A$11="","",Responsáveis!A11) | C34: =IF(Responsáveis!$A$11="","",Responsáveis!E11) | D34: =IF(Responsáveis!$A$11="","",Responsáveis!F11) | E34: =IF(Responsáveis!$A$11="","",Responsáveis!G11) | F34: =IF(Responsáveis!$A$11="","",Responsáveis!H11)
B35: =IF(Responsáveis!$A$12="","",Responsáveis!A12) | C35: =IF(Responsáveis!$A$12="","",Responsáveis!E12) | D35: =IF(Responsáveis!$A$12="","",Responsáveis!F12) | E35: =IF(Responsáveis!$A$12="","",Responsáveis!G12) | F35: =IF(Responsáveis!$A$12="","",Responsáveis!H12)
B36: =IF(Responsáveis!$A$13="","",Responsáveis!A13) | C36: =IF(Responsáveis!$A$13="","",Responsáveis!E13) | D36: =IF(Responsáveis!$A$13="","",Responsáveis!F13) | E36: =IF(Responsáveis!$A$13="","",Responsáveis!G13) | F36: =IF(Responsáveis!$A$13="","",Responsáveis!H13)
B37: =IF(Responsáveis!$A$14="","",Responsáveis!A14) | C37: =IF(Responsáveis!$A$14="","",Responsáveis!E14) | D37: =IF(Responsáveis!$A$14="","",Responsáveis!F14) | E37: =IF(Responsáveis!$A$14="","",Responsáveis!G14) | F37: =IF(Responsáveis!$A$14="","",Responsáveis!H14)
B55: 🎤 POR ARTISTA
B56: Artista | C56: Gestor da conta | D56: Próximo lançamento | E56: Abertas | F56: 🔴 Atrasadas | G56: Situação
B57: =IF(Artistas!$A$5="","",Artistas!A5) -> Luna Ribeiro | C57: =IF(Artistas!$A$5="","",Artistas!C5) -> Elisa Rocha | D57: =IF(Artistas!$A$5="","",Artistas!H5) -> 46311 | E57: =IF(Artistas!$A$5="","",Artistas!I5) -> 5 | F57: =IF(Artistas!$A$5="","",Artistas!J5) -> 2 | G57: =IF(Artistas!$A$5="","",Artistas!K5) -> 🔴 Cobrar equipe
B58: =IF(Artistas!$A$6="","",Artistas!A6) -> MC Taveira | C58: =IF(Artistas!$A$6="","",Artistas!C6) -> Elisa Rocha | D58: =IF(Artistas!$A$6="","",Artistas!H6) -> 46325 | E58: =IF(Artistas!$A$6="","",Artistas!I6) -> 4 | F58: =IF(Artistas!$A$6="","",Artistas!J6) -> 0 | G58: =IF(Artistas!$A$6="","",Artistas!K6) -> 🟡 Em execução
B59: =IF(Artistas!$A$7="","",Artistas!A7) -> Banda Aurora | C59: =IF(Artistas!$A$7="","",Artistas!C7) -> Bruno Lima | D59: =IF(Artistas!$A$7="","",Artistas!H7) -> — | E59: =IF(Artistas!$A$7="","",Artistas!I7) -> 1 | F59: =IF(Artistas!$A$7="","",Artistas!J7) -> 0 | G59: =IF(Artistas!$A$7="","",Artistas!K7) -> 🟡 Em execução
B60: =IF(Artistas!$A$8="","",Artistas!A8) | C60: =IF(Artistas!$A$8="","",Artistas!C8) | D60: =IF(Artistas!$A$8="","",Artistas!H8) | E60: =IF(Artistas!$A$8="","",Artistas!I8) | F60: =IF(Artistas!$A$8="","",Artistas!J8) | G60: =IF(Artistas!$A$8="","",Artistas!K8)
...

Sheet Lançamentos
A1: Artista | B1: Lançamento (faixa / EP) | C1: Data de lançamento | D1: Etapa | E1: Responsável | F1: Prazo da etapa | G1: Status | H1: Dias p/ prazo | I1: Alerta | J1: Última cobrança | K1: Observações | L1: chave
A2: Luna Ribeiro | B2: Maré Alta | C2: 46311 | D2: Briefing / planejamento | E2: Elisa Rocha | F2: =IF(OR(C2="",D2=""),"",IFERROR(C2-INDEX(Listas!$B$5:$B$30,MATCH(D2,Listas!$A$5:$A$30,0)),"")) -> 46281 | G2: Concluído | H2: =IF(OR(A2="",F2="",G2="Concluído"),"",F2-TODAY()) | I2: =IF(A2="","",IF(G2="Concluído","✅ Concluído",IF(F2="","⚪ Sem prazo",IF(H2<0,"🔴 COBRAR · "&-H2&" dia(s) atrasado",IF(H2=0,"🟠 Vence HOJE",IF(H2<=3,"🟠 Vence em "&H2&" dia(s)","🟢 No prazo")))))) -> ✅ Concluído | L2: =IF(OR(A2="",G2="Concluído",F2=""),"",IF(F2<=TODAY()+3,F2+ROW()/1000000,""))
A3: Luna Ribeiro | B3: Maré Alta | C3: 46311 | D3: Capa / arte | E3: Ana Souza | F3: =IF(OR(C3="",D3=""),"",IFERROR(C3-INDEX(Listas!$B$5:$B$30,MATCH(D3,Listas!$A$5:$A$30,0)),"")) -> 46290 | G3: Concluído | H3: =IF(OR(A3="",F3="",G3="Concluído"),"",F3-TODAY()) | I3: =IF(A3="","",IF(G3="Concluído","✅ Concluído",IF(F3="","⚪ Sem prazo",IF(H3<0,"🔴 COBRAR · "&-H3&" dia(s) atrasado",IF(H3=0,"🟠 Vence HOJE",IF(H3<=3,"🟠 Vence em "&H3&" dia(s)","🟢 No prazo")))))) -> ✅ Concluído | L3: =IF(OR(A3="",G3="Concluído",F3=""),"",IF(F3<=TODAY()+3,F3+ROW()/1000000,""))
A4: Luna Ribeiro | B4: Maré Alta | C4: 46311 | D4: Upload na distribuidora | E4: Bruno Lima | F4: =IF(OR(C4="",D4=""),"",IFERROR(C4-INDEX(Listas!$B$5:$B$30,MATCH(D4,Listas!$A$5:$A$30,0)),"")) -> 46297 | G4: Concluído | H4: =IF(OR(A4="",F4="",G4="Concluído"),"",F4-TODAY()) | I4: =IF(A4="","",IF(G4="Concluído","✅ Concluído",IF(F4="","⚪ Sem prazo",IF(H4<0,"🔴 COBRAR · "&-H4&" dia(s) atrasado",IF(H4=0,"🟠 Vence HOJE",IF(H4<=3,"🟠 Vence em "&H4&" dia(s)","🟢 No prazo")))))) -> ✅ Concluído | L4: =IF(OR(A4="",G4="Concluído",F4=""),"",IF(F4<=TODAY()+3,F4+ROW()/1000000,""))
A5: Luna Ribeiro | B5: Maré Alta | C5: 46311 | D5: Pitch editorial Spotify | E5: Bruno Lima | F5: =IF(OR(C5="",D5=""),"",IFERROR(C5-INDEX(Listas!$B$5:$B$30,MATCH(D5,Listas!$A$5:$A$30,0)),"")) -> 46301 | G5: Em andamento | H5: =IF(OR(A5="",F5="",G5="Concluído"),"",F5-TODAY()) -> -3 | I5: =IF(A5="","",IF(G5="Concluído","✅ Concluído",IF(F5="","⚪ Sem prazo",IF(H5<0,"🔴 COBRAR · "&-H5&" dia(s) atrasado",IF(H5=0,"🟠 Vence HOJE",IF(H5<=3,"🟠 Vence em "&H5&" dia(s)","🟢 No prazo")))))) -> 🔴 COBRAR · 3 dia(s) atrasado | J5: 46303 | K5: Prazo do Spotify é crítico! | L5: =IF(OR(A5="",G5="Concluído",F5=""),"",IF(F5<=TODAY()+3,F5+ROW()/1000000,"")) -> 46301
A6: Luna Ribeiro | B6: Maré Alta | C6: 46311 | D6: Pré-save | E6: Carla Mendes | F6: =IF(OR(C6="",D6=""),"",IFERROR(C6-INDEX(Listas!$B$5:$B$30,MATCH(D6,Listas!$A$5:$A$30,0)),"")) -> 46301 | G6: Não iniciado | H6: =IF(OR(A6="",F6="",G6="Concluído"),"",F6-TODAY()) -> -3 | I6: =IF(A6="","",IF(G6="Concluído","✅ Concluído",IF(F6="","⚪ Sem prazo",IF(H6<0,"🔴 COBRAR · "&-H6&" dia(s) atrasado",IF(H6=0,"🟠 Vence HOJE",IF(H6<=3,"🟠 Vence em "&H6&" dia(s)","🟢 No prazo")))))) -> 🔴 COBRAR · 3 dia(s) atrasado | L6: =IF(OR(A6="",G6="Concluído",F6=""),"",IF(F6<=TODAY()+3,F6+ROW()/1000000,"")) -> 46301
A7: Luna Ribeiro | B7: Maré Alta | C7: 46311 | D7: Release / assessoria | E7: Elisa Rocha | F7: =IF(OR(C7="",D7=""),"",IFERROR(C7-INDEX(Listas!$B$5:$B$30,MATCH(D7,Listas!$A$5:$A$30,0)),"")) -> 46304 | G7: Em andamento | H7: =IF(OR(A7="",F7="",G7="Concluído"),"",F7-TODAY()) -> 0 | I7: =IF(A7="","",IF(G7="Concluído","✅ Concluído",IF(F7="","⚪ Sem prazo",IF(H7<0,"🔴 COBRAR · "&-H7&" dia(s) atrasado",IF(H7=0,"🟠 Vence HOJE",IF(H7<=3,"🟠 Vence em "&H7&" dia(s)","🟢 No prazo")))))) -> 🟠 Vence HOJE | L7: =IF(OR(A7="",G7="Concluído",F7=""),"",IF(F7<=TODAY()+3,F7+ROW()/1000000,"")) -> 46304
A8: Luna Ribeiro | B8: Maré Alta | C8: 46311 | D8: Conteúdo para redes (teasers) | E8: Carla Mendes | F8: =IF(OR(C8="",D8=""),"",IFERROR(C8-INDEX(Listas!$B$5:$B$30,MATCH(D8,Listas!$A$5:$A$30,0)),"")) -> 46304 | G8: Aguardando artista | H8: =IF(OR(A8="",F8="",G8="Concluído"),"",F8-TODAY()) -> 0 | I8: =IF(A8="","",IF(G8="Concluído","✅ Concluído",IF(F8="","⚪ Sem prazo",IF(H8<0,"🔴 COBRAR · "&-H8&" dia(s) atrasado",IF(H8=0,"🟠 Vence HOJE",IF(H8<=3,"🟠 Vence em "&H8&" dia(s)","🟢 No prazo")))))) -> 🟠 Vence HOJE | K8: Artista vai mandar vídeos de bastidor | L8: =IF(OR(A8="",G8="Concluído",F8=""),"",IF(F8<=TODAY()+3,F8+ROW()/1000000,"")) -> 46304
A9: Luna Ribeiro | B9: Maré Alta | C9: 46311 | D9: Campanha de tráfego (Ads) | E9: Diego Alves | F9: =IF(OR(C9="",D9=""),"",IFERROR(C9-INDEX(Listas!$B$5:$B$30,MATCH(D9,Listas!$A$5:$A$30,0)),"")) -> 46311 | G9: Não iniciado | H9: =IF(OR(A9="",F9="",G9="Concluído"),"",F9-TODAY()) -> 7 | I9: =IF(A9="","",IF(G9="Concluído","✅ Concluído",IF(F9="","⚪ Sem prazo",IF(H9<0,"🔴 COBRAR · "&-H9&" dia(s) atrasado",IF(H9=0,"🟠 Vence HOJE",IF(H9<=3,"🟠 Vence em "&H9&" dia(s)","🟢 No prazo")))))) -> 🟢 No prazo | L9: =IF(OR(A9="",G9="Concluído",F9=""),"",IF(F9<=TODAY()+3,F9+ROW()/1000000,""))
A10: MC Taveira | B10: Favela Sonha | C10: 46325 | D10: Briefing / planejamento | E10: Elisa Rocha | F10: =IF(OR(C10="",D10=""),"",IFERROR(C10-INDEX(Listas!$B$5:$B$30,MATCH(D10,Listas!$A$5:$A$30,0)),"")) -> 46295 | G10: Concluído | H10: =IF(OR(A10="",F10="",G10="Concluído"),"",F10-TODAY()) | I10: =IF(A10="","",IF(G10="Concluído","✅ Concluído",IF(F10="","⚪ Sem prazo",IF(H10<0,"🔴 COBRAR · "&-H10&" dia(s) atrasado",IF(H10=0,"🟠 Vence HOJE",IF(H10<=3,"🟠 Vence em "&H10&" dia(s)","🟢 No prazo")))))) -> ✅ Concluído | L10: =IF(OR(A10="",G10="Concluído",F10=""),"",IF(F10<=TODAY()+3,F10+ROW()/1000000,""))
A11: MC Taveira | B11: Favela Sonha | C11: 46325 | D11: Capa / arte | E11: Ana Souza | F11: =IF(OR(C11="",D11=""),"",IFERROR(C11-INDEX(Listas!$B$5:$B$30,MATCH(D11,Listas!$A$5:$A$30,0)),"")) -> 46304 | G11: Em andamento | H11: =IF(OR(A11="",F11="",G11="Concluído"),"",F11-TODAY()) -> 0 | I11: =IF(A11="","",IF(G11="Concluído","✅ Concluído",IF(F11="","⚪ Sem prazo",IF(H11<0,"🔴 COBRAR · "&-H11&" dia(s) atrasado",IF(H11=0,"🟠 Vence HOJE",IF(H11<=3,"🟠 Vence em "&H11&" dia(s)","🟢 No prazo")))))) -> 🟠 Vence HOJE | K11: 1ª versão aprovada, faltam ajustes | L11: =IF(OR(A11="",G11="Concluído",F11=""),"",IF(F11<=TODAY()+3,F11+ROW()/1000000,"")) -> 46304
A12: MC Taveira | B12: Favela Sonha | C12: 46325 | D12: Upload na distribuidora | E12: Bruno Lima | F12: =IF(OR(C12="",D12=""),"",IFERROR(C12-INDEX(Listas!$B$5:$B$30,MATCH(D12,Listas!$A$5:$A$30,0)),"")) -> 46311 | G12: Não iniciado | H12: =IF(OR(A12="",F12="",G12="Concluído"),"",F12-TODAY()) -> 7 | I12: =IF(A12="","",IF(G12="Concluído","✅ Concluído",IF(F12="","⚪ Sem prazo",IF(H12<0,"🔴 COBRAR · "&-H12&" dia(s) atrasado",IF(H12=0,"🟠 Vence HOJE",IF(H12<=3,"🟠 Vence em "&H12&" dia(s)","🟢 No prazo")))))) -> 🟢 No prazo | L12: =IF(OR(A12="",G12="Concluído",F12=""),"",IF(F12<=TODAY()+3,F12+ROW()/1000000,""))
A13: MC Taveira | B13: Favela Sonha | C13: 46325 | D13: Pitch editorial Spotify | E13: Bruno Lima | F13: =IF(OR(C13="",D13=""),"",IFERROR(C13-INDEX(Listas!$B$5:$B$30,MATCH(D13,Listas!$A$5:$A$30,0)),"")) -> 46315 | G13: Não iniciado | H13: =IF(OR(A13="",F13="",G13="Concluído"),"",F13-TODAY()) -> 11 | I13: =IF(A13="","",IF(G13="Concluído","✅ Concluído",IF(F13="","⚪ Sem prazo",IF(H13<0,"🔴 COBRAR · "&-H13&" dia(s) atrasado",IF(H13=0,"🟠 Vence HOJE",IF(H13<=3,"🟠 Vence em "&H13&" dia(s)","🟢 No prazo")))))) -> 🟢 No prazo | L13: =IF(OR(A13="",G13="Concluído",F13=""),"",IF(F13<=TODAY()+3,F13+ROW()/1000000,""))
A14: MC Taveira | B14: Favela Sonha | C14: 46325 | D14: Visualizer / clipe | E14: Ana Souza | F14: =IF(OR(C14="",D14=""),"",IFERROR(C14-INDEX(Listas!$B$5:$B$30,MATCH(D14,Listas!$A$5:$A$30,0)),"")) -> 46322 | G14: Não iniciado | H14: =IF(OR(A14="",F14="",G14="Concluído"),"",F14-TODAY()) -> 18 | I14: =IF(A14="","",IF(G14="Concluído","✅ Concluído",IF(F14="","⚪ Sem prazo",IF(H14<0,"🔴 COBRAR · "&-H14&" dia(s) atrasado",IF(H14=0,"🟠 Vence HOJE",IF(H14<=3,"🟠 Vence em "&H14&" dia(s)","🟢 No prazo")))))) -> 🟢 No prazo | L14: =IF(OR(A14="",G14="Concluído",F14=""),"",IF(F14<=TODAY()+3,F14+ROW()/1000000,""))
A15: Banda Aurora | B15: Céu de Outubro | C15: 46290 | D15: Campanha de tráfego (Ads) | E15: Diego Alves | F15: =IF(OR(C15="",D15=""),"",IFERROR(C15-INDEX(Listas!$B$5:$B$30,MATCH(D15,Listas!$A$5:$A$30,0)),"")) -> 46290 | G15: Concluído | H15: =IF(OR(A15="",F15="",G15="Concluído"),"",F15-TODAY()) | I15: =IF(A15="","",IF(G15="Concluído","✅ Concluído",IF(F15="","⚪ Sem prazo",IF(H15<0,"🔴 COBRAR · "&-H15&" dia(s) atrasado",IF(H15=0,"🟠 Vence HOJE",IF(H15<=3,"🟠 Vence em "&H15&" dia(s)","🟢 No prazo")))))) -> ✅ Concluído | L15: =IF(OR(A15="",G15="Concluído",F15=""),"",IF(F15<=TODAY()+3,F15+ROW()/1000000,""))
A16: Banda Aurora | B16: Céu de Outubro | C16: 46290 | D16: Relatório pós-lançamento | E16: Diego Alves | F16: =IF(OR(C16="",D16=""),"",IFERROR(C16-INDEX(Listas!$B$5:$B$30,MATCH(D16,Listas!$A$5:$A$30,0)),"")) -> 46304 | G16: Em andamento | H16: =IF(OR(A16="",F16="",G16="Concluído"),"",F16-TODAY()) -> 0 | I16: =IF(A16="","",IF(G16="Concluído","✅ Concluído",IF(F16="","⚪ Sem prazo",IF(H16<0,"🔴 COBRAR · "&-H16&" dia(s) atrasado",IF(H16=0,"🟠 Vence HOJE",IF(H16<=3,"🟠 Vence em "&H16&" dia(s)","🟢 No prazo")))))) -> 🟠 Vence HOJE | K16: Enviar para o artista na reunião mensal | L16: =IF(OR(A16="",G16="Concluído",F16=""),"",IF(F16<=TODAY()+3,F16+ROW()/1000000,"")) -> 46304
F17: =IF(OR(C17="",D17=""),"",IFERROR(C17-INDEX(Listas!$B$5:$B$30,MATCH(D17,Listas!$A$5:$A$30,0)),"")) | H17: =IF(OR(A17="",F17="",G17="Concluído"),"",F17-TODAY()) | I17: =IF(A17="","",IF(G17="Concluído","✅ Concluído",IF(F17="","⚪ Sem prazo",IF(H17<0,"🔴 COBRAR · "&-H17&" dia(s) atrasado",IF(H17=0,"🟠 Vence HOJE",IF(H17<=3,"🟠 Vence em "&H17&" dia(s)","🟢 No prazo")))))) | L17: =IF(OR(A17="",G17="Concluído",F17=""),"",IF(F17<=TODAY()+3,F17+ROW()/1000000,""))
F18: =IF(OR(C18="",D18=""),"",IFERROR(C18-INDEX(Listas!$B$5:$B$30,MATCH(D18,Listas!$A$5:$A$30,0)),"")) | H18: =IF(OR(A18="",F18="",G18="Concluído"),"",F18-TODAY()) | I18: =IF(A18="","",IF(G18="Concluído","✅ Concluído",IF(F18="","⚪ Sem prazo",IF(H18<0,"🔴 COBRAR · "&-H18&" dia(s) atrasado",IF(H18=0,"🟠 Vence HOJE",IF(H18<=3,"🟠 Vence em "&H18&" dia(s)","🟢 No prazo")))))) | L18: =IF(OR(A18="",G18="Concluído",F18=""),"",IF(F18<=TODAY()+3,F18+ROW()/1000000,""))
F19: =IF(OR(C19="",D19=""),"",IFERROR(C19-INDEX(Listas!$B$5:$B$30,MATCH(D19,Listas!$A$5:$A$30,0)),"")) | H19: =IF(OR(A19="",F19="",G19="Concluído"),"",F19-TODAY()) | I19: =IF(A19="","",IF(G19="Concluído","✅ Concluído",IF(F19="","⚪ Sem prazo",IF(H19<0,"🔴 COBRAR · "&-H19&" dia(s) atrasado",IF(H19=0,"🟠 Vence HOJE",IF(H19<=3,"🟠 Vence em "&H19&" dia(s)","🟢 No prazo")))))) | L19: =IF(OR(A19="",G19="Concluído",F19=""),"",IF(F19<=TODAY()+3,F19+ROW()/1000000,""))
F20: =IF(OR(C20="",D20=""),"",IFERROR(C20-INDEX(Listas!$B$5:$B$30,MATCH(D20,Listas!$A$5:$A$30,0)),"")) | H20: =IF(OR(A20="",F20="",G20="Concluído"),"",F20-TODAY()) | I20: =IF(A20="","",IF(G20="Concluído","✅ Concluído",IF(F20="","⚪ Sem prazo",IF(H20<0,"🔴 COBRAR · "&-H20&" dia(s) atrasado",IF(H20=0,"🟠 Vence HOJE",IF(H20<=3,"🟠 Vence em "&H20&" dia(s)","🟢 No prazo")))))) | L20: =IF(OR(A20="",G20="Concluído",F20=""),"",IF(F20<=TODAY()+3,F20+ROW()/1000000,""))
F21: =IF(OR(C21="",D21=""),"",IFERROR(C21-INDEX(Listas!$B$5:$B$30,MATCH(D21,Listas!$A$5:$A$30,0)),"")) | H21: =IF(OR(A21="",F21="",G21="Concluído"),"",F21-TODAY()) | I21: =IF(A21="","",IF(G21="Concluído","✅ Concluído",IF(F21="","⚪ Sem prazo",IF(H21<0,"🔴 COBRAR · "&-H21&" dia(s) atrasado",IF(H21=0,"🟠 Vence HOJE",IF(H21<=3,"🟠 Vence em "&H21&" dia(s)","🟢 No prazo")))))) | L21: =IF(OR(A21="",G21="Concluído",F21=""),"",IF(F21<=TODAY()+3,F21+ROW()/1000000,""))
F22: =IF(OR(C22="",D22=""),"",IFERROR(C22-INDEX(Listas!$B$5:$B$30,MATCH(D22,Listas!$A$5:$A$30,0)),"")) | H22: =IF(OR(A22="",F22="",G22="Concluído"),"",F22-TODAY()) | I22: =IF(A22="","",IF(G22="Concluído","✅ Concluído",IF(F22="","⚪ Sem prazo",IF(H22<0,"🔴 COBRAR · "&-H22&" dia(s) atrasado",IF(H22=0,"🟠 Vence HOJE",IF(H22<=3,"🟠 Vence em "&H22&" dia(s)","🟢 No prazo")))))) | L22: =IF(OR(A22="",G22="Concluído",F22=""),"",IF(F22<=TODAY()+3,F22+ROW()/1000000,""))
F23: =IF(OR(C23="",D23=""),"",IFERROR(C23-INDEX(Listas!$B$5:$B$30,MATCH(D23,Listas!$A$5:$A$30,0)),"")) | H23: =IF(OR(A23="",F23="",G23="Concluído"),"",F23-TODAY()) | I23: =IF(A23="","",IF(G23="Concluído","✅ Concluído",IF(F23="","⚪ Sem prazo",IF(H23<0,"🔴 COBRAR · "&-H23&" dia(s) atrasado",IF(H23=0,"🟠 Vence HOJE",IF(H23<=3,"🟠 Vence em "&H23&" dia(s)","🟢 No prazo")))))) | L23: =IF(OR(A23="",G23="Concluído",F23=""),"",IF(F23<=TODAY()+3,F23+ROW()/1000000,""))
F24: =IF(OR(C24="",D24=""),"",IFERROR(C24-INDEX(Listas!$B$5:$B$30,MATCH(D24,Listas!$A$5:$A$30,0)),"")) | H24: =IF(OR(A24="",F24="",G24="Concluído"),"",F24-TODAY()) | I24: =IF(A24="","",IF(G24="Concluído","✅ Concluído",IF(F24="","⚪ Sem prazo",IF(H24<0,"🔴 COBRAR · "&-H24&" dia(s) atrasado",IF(H24=0,"🟠 Vence HOJE",IF(H24<=3,"🟠 Vence em "&H24&" dia(s)","🟢 No prazo")))))) | L24: =IF(OR(A24="",G24="Concluído",F24=""),"",IF(F24<=TODAY()+3,F24+ROW()/1000000,""))
F25: =IF(OR(C25="",D25=""),"",IFERROR(C25-INDEX(Listas!$B$5:$B$30,MATCH(D25,Listas!$A$5:$A$30,0)),"")) | H25: =IF(OR(A25="",F25="",G25="Concluído"),"",F25-TODAY()) | I25: =IF(A25="","",IF(G25="Concluído","✅ Concluído",IF(F25="","⚪ Sem prazo",IF(H25<0,"🔴 COBRAR · "&-H25&" dia(s) atrasado",IF(H25=0,"🟠 Vence HOJE",IF(H25<=3,"🟠 Vence em "&H25&" dia(s)","🟢 No prazo")))))) | L25: =IF(OR(A25="",G25="Concluído",F25=""),"",IF(F25<=TODAY()+3,F25+ROW()/1000000,""))
F26: =IF(OR(C26="",D26=""),"",IFERROR(C26-INDEX(Listas!$B$5:$B$30,MATCH(D26,Listas!$A$5:$A$30,0)),"")) | H26: =IF(OR(A26="",F26="",G26="Concluído"),"",F26-TODAY()) | I26: =IF(A26="","",IF(G26="Concluído","✅ Concluído",IF(F26="","⚪ Sem prazo",IF(H26<0,"🔴 COBRAR · "&-H26&" dia(s) atrasado",IF(H26=0,"🟠 Vence HOJE",IF(H26<=3,"🟠 Vence em "&H26&" dia(s)","🟢 No prazo")))))) | L26: =IF(OR(A26="",G26="Concluído",F26=""),"",IF(F26<=TODAY()+3,F26+ROW()/1000000,""))
F27: =IF(OR(C27="",D27=""),"",IFERROR(C27-INDEX(Listas!$B$5:$B$30,MATCH(D27,Listas!$A$5:$A$30,0)),"")) | H27: =IF(OR(A27="",F27="",G27="Concluído"),"",F27-TODAY()) | I27: =IF(A27="","",IF(G27="Concluído","✅ Concluído",IF(F27="","⚪ Sem prazo",IF(H27<0,"🔴 COBRAR · "&-H27&" dia(s) atrasado",IF(H27=0,"🟠 Vence HOJE",IF(H27<=3,"🟠 Vence em "&H27&" dia(s)","🟢 No prazo")))))) | L27: =IF(OR(A27="",G27="Concluído",F27=""),"",IF(F27<=TODAY()+3,F27+ROW()/1000000,""))
F28: =IF(OR(C28="",D28=""),"",IFERROR(C28-INDEX(Listas!$B$5:$B$30,MATCH(D28,Listas!$A$5:$A$30,0)),"")) | H28: =IF(OR(A28="",F28="",G28="Concluído"),"",F28-TODAY()) | I28: =IF(A28="","",IF(G28="Concluído","✅ Concluído",IF(F28="","⚪ Sem prazo",IF(H28<0,"🔴 COBRAR · "&-H28&" dia(s) atrasado",IF(H28=0,"🟠 Vence HOJE",IF(H28<=3,"🟠 Vence em "&H28&" dia(s)","🟢 No prazo")))))) | L28: =IF(OR(A28="",G28="Concluído",F28=""),"",IF(F28<=TODAY()+3,F28+ROW()/1000000,""))
... F401: =IF(OR(C401="",D401=""),"",IFERROR(C401-INDEX(Listas!$B$5:$B$30,MATCH(D401,Listas!$A$5:$A$30,0)),"")) | H401: =IF(OR(A401="",F401="",G401="Concluído"),"",F401-TODAY()) | I401: =IF(A401="","",IF(G401="Concluído","✅ Concluído",IF(F401="","⚪ Sem prazo",IF(H401<0,"🔴 COBRAR · "&-H401&" dia(s) atrasado",IF(H401=0,"🟠 Vence HOJE",IF(H401<=3,"🟠 Vence em "&H401&" dia(s)","🟢 No prazo")))))) | L401: =IF(OR(A401="",G401="Concluído",F401=""),"",IF(F401<=TODAY()+3,F401+ROW()/1000000,""))

Sheet Artistas
A1: Artistas no Plano Propulse
A2: Uma linha por artista. Amarelo = você preenche; cinza = calculado automaticamente.
A4: Artista | B4: Gênero | C4: Gestor da conta | D4: Contato do artista | E4: Entrada no Propulse | F4: Status no plano | G4: Mês no plano | H4: Próximo lançamento | I4: Tarefas abertas | J4: 🔴 Atrasadas | K4: Situação | L4: Observações
A5: Luna Ribeiro | B5: Pop | C5: Elisa Rocha | D5: (11) 98888-0001 | E5: 46204 | F5: Ativo | G5: =IF(OR(A5="",E5=""),"",DATEDIF(E5,TODAY(),"m")+1) -> 4 | H5: =IF(A5="","",IF(_xlfn.MINIFS(Lançamentos!$C$2:$C$401,Lançamentos!$A$2:$A$401,A5,Lançamentos!$C$2:$C$401,">="&TODAY())=0,"—",_xlfn.MINIFS(Lançamentos!$C$2:$C$401,Lançamentos!$A$2:$A$401,A5,Lançamentos!$C$2:$C$401,">="&TODAY()))) -> 46311 | I5: =IF(A5="","",COUNTIFS(Lançamentos!$A$2:$A$401,A5,Lançamentos!$G$2:$G$401,"<>Concluído")) -> 5 | J5: =IF(A5="","",COUNTIFS(Lançamentos!$A$2:$A$401,A5,Lançamentos!$G$2:$G$401,"<>Concluído",Lançamentos!$F$2:$F$401,"<"&TODAY())) -> 2 | K5: =IF(A5="","",IF(F5<>"Ativo","⚪ "&F5,IF(J5>0,"🔴 Cobrar equipe",IF(I5>0,"🟡 Em execução","🟢 Em dia")))) -> 🔴 Cobrar equipe
A6: MC Taveira | B6: Funk | C6: Elisa Rocha | D6: (21) 98888-0002 | E6: 46249 | F6: Ativo | G6: =IF(OR(A6="",E6=""),"",DATEDIF(E6,TODAY(),"m")+1) -> 2 | H6: =IF(A6="","",IF(_xlfn.MINIFS(Lançamentos!$C$2:$C$401,Lançamentos!$A$2:$A$401,A6,Lançamentos!$C$2:$C$401,">="&TODAY())=0,"—",_xlfn.MINIFS(Lançamentos!$C$2:$C$401,Lançamentos!$A$2:$A$401,A6,Lançamentos!$C$2:$C$401,">="&TODAY()))) -> 46325 | I6: =IF(A6="","",COUNTIFS(Lançamentos!$A$2:$A$401,A6,Lançamentos!$G$2:$G$401,"<>Concluído")) -> 4 | J6: =IF(A6="","",COUNTIFS(Lançamentos!$A$2:$A$401,A6,Lançamentos!$G$2:$G$401,"<>Concluído",Lançamentos!$F$2:$F$401,"<"&TODAY())) -> 0 | K6: =IF(A6="","",IF(F6<>"Ativo","⚪ "&F6,IF(J6>0,"🔴 Cobrar equipe",IF(I6>0,"🟡 Em execução","🟢 Em dia")))) -> 🟡 Em execução
A7: Banda Aurora | B7: Indie / rock | C7: Bruno Lima | D7: (31) 98888-0003 | E7: 46152 | F7: Ativo | G7: =IF(OR(A7="",E7=""),"",DATEDIF(E7,TODAY(),"m")+1) -> 5 | H7: =IF(A7="","",IF(_xlfn.MINIFS(Lançamentos!$C$2:$C$401,Lançamentos!$A$2:$A$401,A7,Lançamentos!$C$2:$C$401,">="&TODAY())=0,"—",_xlfn.MINIFS(Lançamentos!$C$2:$C$401,Lançamentos!$A$2:$A$401,A7,Lançamentos!$C$2:$C$401,">="&TODAY()))) -> — | I7: =IF(A7="","",COUNTIFS(Lançamentos!$A$2:$A$401,A7,Lançamentos!$G$2:$G$401,"<>Concluído")) -> 1 | J7: =IF(A7="","",COUNTIFS(Lançamentos!$A$2:$A$401,A7,Lançamentos!$G$2:$G$401,"<>Concluído",Lançamentos!$F$2:$F$401,"<"&TODAY())) -> 0 | K7: =IF(A7="","",IF(F7<>"Ativo","⚪ "&F7,IF(J7>0,"🔴 Cobrar equipe",IF(I7>0,"🟡 Em execução","🟢 Em dia")))) -> 🟡 Em execução | L7: Renovação do plano em novembro
G8: =IF(OR(A8="",E8=""),"",DATEDIF(E8,TODAY(),"m")+1) | H8: =IF(A8="","",IF(_xlfn.MINIFS(Lançamentos!$C$2:$C$401,Lançamentos!$A$2:$A$401,A8,Lançamentos!$C$2:$C$401,">="&TODAY())=0,"—",_xlfn.MINIFS(Lançamentos!$C$2:$C$401,Lançamentos!$A$2:$A$401,A8,Lançamentos!$C$2:$C$401,">="&TODAY()))) | I8: =IF(A8="","",COUNTIFS(Lançamentos!$A$2:$A$401,A8,Lançamentos!$G$2:$G$401,"<>Concluído")) | J8: =IF(A8="","",COUNTIFS(Lançamentos!$A$2:$A$401,A8,Lançamentos!$G$2:$G$401,"<>Concluído",Lançamentos!$F$2:$F$401,"<"&TODAY())) | K8: =IF(A8="","",IF(F8<>"Ativo","⚪ "&F8,IF(J8>0,"🔴 Cobrar equipe",IF(I8>0,"🟡 Em execução","🟢 Em dia"))))
G9: =IF(OR(A9="",E9=""),"",DATEDIF(E9,TODAY(),"m")+1) | H9: =IF(A9="","",IF(_xlfn.MINIFS(Lançamentos!$C$2:$C$401,Lançamentos!$A$2:$A$401,A9,Lançamentos!$C$2:$C$401,">="&TODAY())=0,"—",_xlfn.MINIFS(Lançamentos!$C$2:$C$401,Lançamentos!$A$2:$A$401,A9,Lançamentos!$C$2:$C$401,">="&TODAY()))) | I9: =IF(A9="","",COUNTIFS(Lançamentos!$A$2:$A$401,A9,Lançamentos!$G$2:$G$401,"<>Concluído")) | J9: =IF(A9="","",COUNTIFS(Lançamentos!$A$2:$A$401,A9,Lançamentos!$G$2:$G$401,"<>Concluído",Lançamentos!$F$2:$F$401,"<"&TODAY())) | K9: =IF(A9="","",IF(F9<>"Ativo","⚪ "&F9,IF(J9>0,"🔴 Cobrar equipe",IF(I9>0,"🟡 Em execução","🟢 Em dia"))))
G10: =IF(OR(A10="",E10=""),"",DATEDIF(E10,TODAY(),"m")+1) | H10: =IF(A10="","",IF(_xlfn.MINIFS(Lançamentos!$C$2:$C$401,Lançamentos!$A$2:$A$401,A10,Lançamentos!$C$2:$C$401,">="&TODAY())=0,"—",_xlfn.MINIFS(Lançamentos!$C$2:$C$401,Lançamentos!$A$2:$A$401,A10,Lançamentos!$C$2:$C$401,">="&TODAY()))) | I10: =IF(A10="","",COUNTIFS(Lançamentos!$A$2:$A$401,A10,Lançamentos!$G$2:$G$401,"<>Concluído")) | J10: =IF(A10="","",COUNTIFS(Lançamentos!$A$2:$A$401,A10,Lançamentos!$G$2:$G$401,"<>Concluído",Lançamentos!$F$2:$F$401,"<"&TODAY())) | K10: =IF(A10="","",IF(F10<>"Ativo","⚪ "&F10,IF(J10>0,"🔴 Cobrar equipe",IF(I10>0,"🟡 Em execução","🟢 Em dia"))))
G11: =IF(OR(A11="",E11=""),"",DATEDIF(E11,TODAY(),"m")+1) | H11: =IF(A11="","",IF(_xlfn.MINIFS(Lançamentos!$C$2:$C$401,Lançamentos!$A$2:$A$401,A11,Lançamentos!$C$2:$C$401,">="&TODAY())=0,"—",_xlfn.MINIFS(Lançamentos!$C$2:$C$401,Lançamentos!$A$2:$A$401,A11,Lançamentos!$C$2:$C$401,">="&TODAY()))) | I11: =IF(A11="","",COUNTIFS(Lançamentos!$A$2:$A$401,A11,Lançamentos!$G$2:$G$401,"<>Concluído")) | J11: =IF(A11="","",COUNTIFS(Lançamentos!$A$2:$A$401,A11,Lançamentos!$G$2:$G$401,"<>Concluído",Lançamentos!$F$2:$F$401,"<"&TODAY())) | K11: =IF(A11="","",IF(F11<>"Ativo","⚪ "&F11,IF(J11>0,"🔴 Cobrar equipe",IF(I11>0,"🟡 Em execução","🟢 Em dia"))))
G12: =IF(OR(A12="",E12=""),"",DATEDIF(E12,TODAY(),"m")+1) | H12: =IF(A12="","",IF(_xlfn.MINIFS(Lançamentos!$C$2:$C$401,Lançamentos!$A$2:$A$401,A12,Lançamentos!$C$2:$C$401,">="&TODAY())=0,"—",_xlfn.MINIFS(Lançamentos!$C$2:$C$401,Lançamentos!$A$2:$A$401,A12,Lançamentos!$C$2:$C$401,">="&TODAY()))) | I12: =IF(A12="","",COUNTIFS(Lançamentos!$A$2:$A$401,A12,Lançamentos!$G$2:$G$401,"<>Concluído")) | J12: =IF(A12="","",COUNTIFS(Lançamentos!$A$2:$A$401,A12,Lançamentos!$G$2:$G$401,"<>Concluído",Lançamentos!$F$2:$F$401,"<"&TODAY())) | K12: =IF(A12="","",IF(F12<>"Ativo","⚪ "&F12,IF(J12>0,"🔴 Cobrar equipe",IF(I12>0,"🟡 Em execução","🟢 Em dia"))))
G13: =IF(OR(A13="",E13=""),"",DATEDIF(E13,TODAY(),"m")+1) | H13: =IF(A13="","",IF(_xlfn.MINIFS(Lançamentos!$C$2:$C$401,Lançamentos!$A$2:$A$401,A13,Lançamentos!$C$2:$C$401,">="&TODAY())=0,"—",_xlfn.MINIFS(Lançamentos!$C$2:$C$401,Lançamentos!$A$2:$A$401,A13,Lançamentos!$C$2:$C$401,">="&TODAY()))) | I13: =IF(A13="","",COUNTIFS(Lançamentos!$A$2:$A$401,A13,Lançamentos!$G$2:$G$401,"<>Concluído")) | J13: =IF(A13="","",COUNTIFS(Lançamentos!$A$2:$A$401,A13,Lançamentos!$G$2:$G$401,"<>Concluído",Lançamentos!$F$2:$F$401,"<"&TODAY())) | K13: =IF(A13="","",IF(F13<>"Ativo","⚪ "&F13,IF(J13>0,"🔴 Cobrar equipe",IF(I13>0,"🟡 Em execução","🟢 Em dia"))))
G14: =IF(OR(A14="",E14=""),"",DATEDIF(E14,TODAY(),"m")+1) | H14: =IF(A14="","",IF(_xlfn.MINIFS(Lançamentos!$C$2:$C$401,Lançamentos!$A$2:$A$401,A14,Lançamentos!$C$2:$C$401,">="&TODAY())=0,"—",_xlfn.MINIFS(Lançamentos!$C$2:$C$401,Lançamentos!$A$2:$A$401,A14,Lançamentos!$C$2:$C$401,">="&TODAY()))) | I14: =IF(A14="","",COUNTIFS(Lançamentos!$A$2:$A$401,A14,Lançamentos!$G$2:$G$401,"<>Concluído")) | J14: =IF(A14="","",COUNTIFS(Lançamentos!$A$2:$A$401,A14,Lançamentos!$G$2:$G$401,"<>Concluído",Lançamentos!$F$2:$F$401,"<"&TODAY())) | K14: =IF(A14="","",IF(F14<>"Ativo","⚪ "&F14,IF(J14>0,"🔴 Cobrar equipe",IF(I14>0,"🟡 Em execução","🟢 Em dia"))))
G15: =IF(OR(A15="",E15=""),"",DATEDIF(E15,TODAY(),"m")+1) | H15: =IF(A15="","",IF(_xlfn.MINIFS(Lançamentos!$C$2:$C$401,Lançamentos!$A$2:$A$401,A15,Lançamentos!$C$2:$C$401,">="&TODAY())=0,"—",_xlfn.MINIFS(Lançamentos!$C$2:$C$401,Lançamentos!$A$2:$A$401,A15,Lançamentos!$C$2:$C$401,">="&TODAY()))) | I15: =IF(A15="","",COUNTIFS(Lançamentos!$A$2:$A$401,A15,Lançamentos!$G$2:$G$401,"<>Concluído")) | J15: =IF(A15="","",COUNTIFS(Lançamentos!$A$2:$A$401,A15,Lançamentos!$G$2:$G$401,"<>Concluído",Lançamentos!$F$2:$F$401,"<"&TODAY())) | K15: =IF(A15="","",IF(F15<>"Ativo","⚪ "&F15,IF(J15>0,"🔴 Cobrar equipe",IF(I15>0,"🟡 Em execução","🟢 Em dia"))))
G16: =IF(OR(A16="",E16=""),"",DATEDIF(E16,TODAY(),"m")+1) | H16: =IF(A16="","",IF(_xlfn.MINIFS(Lançamentos!$C$2:$C$401,Lançamentos!$A$2:$A$401,A16,Lançamentos!$C$2:$C$401,">="&TODAY())=0,"—",_xlfn.MINIFS(Lançamentos!$C$2:$C$401,Lançamentos!$A$2:$A$401,A16,Lançamentos!$C$2:$C$401,">="&TODAY()))) | I16: =IF(A16="","",COUNTIFS(Lançamentos!$A$2:$A$401,A16,Lançamentos!$G$2:$G$401,"<>Concluído")) | J16: =IF(A16="","",COUNTIFS(Lançamentos!$A$2:$A$401,A16,Lançamentos!$G$2:$G$401,"<>Concluído",Lançamentos!$F$2:$F$401,"<"&TODAY())) | K16: =IF(A16="","",IF(F16<>"Ativo","⚪ "&F16,IF(J16>0,"🔴 Cobrar equipe",IF(I16>0,"🟡 Em execução","🟢 Em dia"))))
G17: =IF(OR(A17="",E17=""),"",DATEDIF(E17,TODAY(),"m")+1) | H17: =IF(A17="","",IF(_xlfn.MINIFS(Lançamentos!$C$2:$C$401,Lançamentos!$A$2:$A$401,A17,Lançamentos!$C$2:$C$401,">="&TODAY())=0,"—",_xlfn.MINIFS(Lançamentos!$C$2:$C$401,Lançamentos!$A$2:$A$401,A17,Lançamentos!$C$2:$C$401,">="&TODAY()))) | I17: =IF(A17="","",COUNTIFS(Lançamentos!$A$2:$A$401,A17,Lançamentos!$G$2:$G$401,"<>Concluído")) | J17: =IF(A17="","",COUNTIFS(Lançamentos!$A$2:$A$401,A17,Lançamentos!$G$2:$G$401,"<>Concluído",Lançamentos!$F$2:$F$401,"<"&TODAY())) | K17: =IF(A17="","",IF(F17<>"Ativo","⚪ "&F17,IF(J17>0,"🔴 Cobrar equipe",IF(I17>0,"🟡 Em execução","🟢 Em dia"))))
G18: =IF(OR(A18="",E18=""),"",DATEDIF(E18,TODAY(),"m")+1) | H18: =IF(A18="","",IF(_xlfn.MINIFS(Lançamentos!$C$2:$C$401,Lançamentos!$A$2:$A$401,A18,Lançamentos!$C$2:$C$401,">="&TODAY())=0,"—",_xlfn.MINIFS(Lançamentos!$C$2:$C$401,Lançamentos!$A$2:$A$401,A18,Lançamentos!$C$2:$C$401,">="&TODAY()))) | I18: =IF(A18="","",COUNTIFS(Lançamentos!$A$2:$A$401,A18,Lançamentos!$G$2:$G$401,"<>Concluído")) | J18: =IF(A18="","",COUNTIFS(Lançamentos!$A$2:$A$401,A18,Lançamentos!$G$2:$G$401,"<>Concluído",Lançamentos!$F$2:$F$401,"<"&TODAY())) | K18: =IF(A18="","",IF(F18<>"Ativo","⚪ "&F18,IF(J18>0,"🔴 Cobrar equipe",IF(I18>0,"🟡 Em execução","🟢 Em dia"))))
G19: =IF(OR(A19="",E19=""),"",DATEDIF(E19,TODAY(),"m")+1) | H19: =IF(A19="","",IF(_xlfn.MINIFS(Lançamentos!$C$2:$C$401,Lançamentos!$A$2:$A$401,A19,Lançamentos!$C$2:$C$401,">="&TODAY())=0,"—",_xlfn.MINIFS(Lançamentos!$C$2:$C$401,Lançamentos!$A$2:$A$401,A19,Lançamentos!$C$2:$C$401,">="&TODAY()))) | I19: =IF(A19="","",COUNTIFS(Lançamentos!$A$2:$A$401,A19,Lançamentos!$G$2:$G$401,"<>Concluído")) | J19: =IF(A19="","",COUNTIFS(Lançamentos!$A$2:$A$401,A19,Lançamentos!$G$2:$G$401,"<>Concluído",Lançamentos!$F$2:$F$401,"<"&TODAY())) | K19: =IF(A19="","",IF(F19<>"Ativo","⚪ "&F19,IF(J19>0,"🔴 Cobrar equipe",IF(I19>0,"🟡 Em execução","🟢 Em dia"))))
... G104: =IF(OR(A104="",E104=""),"",DATEDIF(E104,TODAY(),"m")+1) | H104: =IF(A104="","",IF(_xlfn.MINIFS(Lançamentos!$C$2:$C$401,Lançamentos!$A$2:$A$401,A104,Lançamentos!$C$2:$C$401,">="&TODAY())=0,"—",_xlfn.MINIFS(Lançamentos!$C$2:$C$401,Lançamentos!$A$2:$A$401,A104,Lançamentos!$C$2:$C$401,">="&TODAY()))) | I104: =IF(A104="","",COUNTIFS(Lançamentos!$A$2:$A$401,A104,Lançamentos!$G$2:$G$401,"<>Concluído")) | J104: =IF(A104="","",COUNTIFS(Lançamentos!$A$2:$A$401,A104,Lançamentos!$G$2:$G$401,"<>Concluído",Lançamentos!$F$2:$F$401,"<"&TODAY())) | K104: =IF(A104="","",IF(F104<>"Ativo","⚪ "&F104,IF(J104>0,"🔴 Cobrar equipe",IF(I104>0,"🟡 Em execução","🟢 Em dia"))))

Sheet Responsáveis
A1: Equipe responsável pela execução
A2: Cadastre quem executa cada etapa. As colunas cinza calculam sozinhas.
A4: Responsável | B4: Função | C4: WhatsApp | D4: E-mail | E4: Tarefas abertas | F4: 🔴 Atrasadas | G4: 🟠 Vencem em até 3 dias | H4: Situação
A5: Ana Souza | B5: Design / capas | C5: (11) 90000-0001 | D5: ana@exemplo.com | E5: =IF(A5="","",COUNTIFS(Lançamentos!$E$2:$E$401,A5,Lançamentos!$G$2:$G$401,"<>Concluído")) -> 2 | F5: =IF(A5="","",COUNTIFS(Lançamentos!$E$2:$E$401,A5,Lançamentos!$G$2:$G$401,"<>Concluído",Lançamentos!$F$2:$F$401,"<"&TODAY())) -> 0 | G5: =IF(A5="","",COUNTIFS(Lançamentos!$E$2:$E$401,A5,Lançamentos!$G$2:$G$401,"<>Concluído",Lançamentos!$F$2:$F$401,">="&TODAY(),Lançamentos!$F$2:$F$401,"<="&TODAY()+3)) -> 1 | H5: =IF(A5="","",IF(F5>0,"🔴 COBRAR hoje",IF(G5>0,"🟠 Lembrar esta semana","🟢 Em dia"))) -> 🟠 Lembrar esta semana
A6: Bruno Lima | B6: Distribuição / pitch | C6: (11) 90000-0002 | D6: bruno@exemplo.com | E6: =IF(A6="","",COUNTIFS(Lançamentos!$E$2:$E$401,A6,Lançamentos!$G$2:$G$401,"<>Concluído")) -> 3 | F6: =IF(A6="","",COUNTIFS(Lançamentos!$E$2:$E$401,A6,Lançamentos!$G$2:$G$401,"<>Concluído",Lançamentos!$F$2:$F$401,"<"&TODAY())) -> 1 | G6: =IF(A6="","",COUNTIFS(Lançamentos!$E$2:$E$401,A6,Lançamentos!$G$2:$G$401,"<>Concluído",Lançamentos!$F$2:$F$401,">="&TODAY(),Lançamentos!$F$2:$F$401,"<="&TODAY()+3)) -> 0 | H6: =IF(A6="","",IF(F6>0,"🔴 COBRAR hoje",IF(G6>0,"🟠 Lembrar esta semana","🟢 Em dia"))) -> 🔴 COBRAR hoje
A7: Carla Mendes | B7: Social media | C7: (11) 90000-0003 | D7: carla@exemplo.com | E7: =IF(A7="","",COUNTIFS(Lançamentos!$E$2:$E$401,A7,Lançamentos!$G$2:$G$401,"<>Concluído")) -> 2 | F7: =IF(A7="","",COUNTIFS(Lançamentos!$E$2:$E$401,A7,Lançamentos!$G$2:$G$401,"<>Concluído",Lançamentos!$F$2:$F$401,"<"&TODAY())) -> 1 | G7: =IF(A7="","",COUNTIFS(Lançamentos!$E$2:$E$401,A7,Lançamentos!$G$2:$G$401,"<>Concluído",Lançamentos!$F$2:$F$401,">="&TODAY(),Lançamentos!$F$2:$F$401,"<="&TODAY()+3)) -> 1 | H7: =IF(A7="","",IF(F7>0,"🔴 COBRAR hoje",IF(G7>0,"🟠 Lembrar esta semana","🟢 Em dia"))) -> 🔴 COBRAR hoje
A8: Diego Alves | B8: Tráfego pago | C8: (11) 90000-0004 | D8: diego@exemplo.com | E8: =IF(A8="","",COUNTIFS(Lançamentos!$E$2:$E$401,A8,Lançamentos!$G$2:$G$401,"<>Concluído")) -> 2 | F8: =IF(A8="","",COUNTIFS(Lançamentos!$E$2:$E$401,A8,Lançamentos!$G$2:$G$401,"<>Concluído",Lançamentos!$F$2:$F$401,"<"&TODAY())) -> 0 | G8: =IF(A8="","",COUNTIFS(Lançamentos!$E$2:$E$401,A8,Lançamentos!$G$2:$G$401,"<>Concluído",Lançamentos!$F$2:$F$401,">="&TODAY(),Lançamentos!$F$2:$F$401,"<="&TODAY()+3)) -> 1 | H8: =IF(A8="","",IF(F8>0,"🔴 COBRAR hoje",IF(G8>0,"🟠 Lembrar esta semana","🟢 Em dia"))) -> 🟠 Lembrar esta semana
A9: Elisa Rocha | B9: Assessoria / gestão | C9: (11) 90000-0005 | D9: elisa@exemplo.com | E9: =IF(A9="","",COUNTIFS(Lançamentos!$E$2:$E$401,A9,Lançamentos!$G$2:$G$401,"<>Concluído")) -> 1 | F9: =IF(A9="","",COUNTIFS(Lançamentos!$E$2:$E$401,A9,Lançamentos!$G$2:$G$401,"<>Concluído",Lançamentos!$F$2:$F$401,"<"&TODAY())) -> 0 | G9: =IF(A9="","",COUNTIFS(Lançamentos!$E$2:$E$401,A9,Lançamentos!$G$2:$G$401,"<>Concluído",Lançamentos!$F$2:$F$401,">="&TODAY(),Lançamentos!$F$2:$F$401,"<="&TODAY()+3)) -> 1 | H9: =IF(A9="","",IF(F9>0,"🔴 COBRAR hoje",IF(G9>0,"🟠 Lembrar esta semana","🟢 Em dia"))) -> 🟠 Lembrar esta semana
E10: =IF(A10="","",COUNTIFS(Lançamentos!$E$2:$E$401,A10,Lançamentos!$G$2:$G$401,"<>Concluído")) | F10: =IF(A10="","",COUNTIFS(Lançamentos!$E$2:$E$401,A10,Lançamentos!$G$2:$G$401,"<>Concluído",Lançamentos!$F$2:$F$401,"<"&TODAY())) | G10: =IF(A10="","",COUNTIFS(Lançamentos!$E$2:$E$401,A10,Lançamentos!$G$2:$G$401,"<>Concluído",Lançamentos!$F$2:$F$401,">="&TODAY(),Lançamentos!$F$2:$F$401,"<="&TODAY()+3)) | H10: =IF(A10="","",IF(F10>0,"🔴 COBRAR hoje",IF(G10>0,"🟠 Lembrar esta semana","🟢 Em dia")))
E11: =IF(A11="","",COUNTIFS(Lançamentos!$E$2:$E$401,A11,Lançamentos!$G$2:$G$401,"<>Concluído")) | F11: =IF(A11="","",COUNTIFS(Lançamentos!$E$2:$E$401,A11,Lançamentos!$G$2:$G$401,"<>Concluído",Lançamentos!$F$2:$F$401,"<"&TODAY())) | G11: =IF(A11="","",COUNTIFS(Lançamentos!$E$2:$E$401,A11,Lançamentos!$G$2:$G$401,"<>Concluído",Lançamentos!$F$2:$F$401,">="&TODAY(),Lançamentos!$F$2:$F$401,"<="&TODAY()+3)) | H11: =IF(A11="","",IF(F11>0,"🔴 COBRAR hoje",IF(G11>0,"🟠 Lembrar esta semana","🟢 Em dia")))
E12: =IF(A12="","",COUNTIFS(Lançamentos!$E$2:$E$401,A12,Lançamentos!$G$2:$G$401,"<>Concluído")) | F12: =IF(A12="","",COUNTIFS(Lançamentos!$E$2:$E$401,A12,Lançamentos!$G$2:$G$401,"<>Concluído",Lançamentos!$F$2:$F$401,"<"&TODAY())) | G12: =IF(A12="","",COUNTIFS(Lançamentos!$E$2:$E$401,A12,Lançamentos!$G$2:$G$401,"<>Concluído",Lançamentos!$F$2:$F$401,">="&TODAY(),Lançamentos!$F$2:$F$401,"<="&TODAY()+3)) | H12: =IF(A12="","",IF(F12>0,"🔴 COBRAR hoje",IF(G12>0,"🟠 Lembrar esta semana","🟢 Em dia")))
E13: =IF(A13="","",COUNTIFS(Lançamentos!$E$2:$E$401,A13,Lançamentos!$G$2:$G$401,"<>Concluído")) | F13: =IF(A13="","",COUNTIFS(Lançamentos!$E$2:$E$401,A13,Lançamentos!$G$2:$G$401,"<>Concluído",Lançamentos!$F$2:$F$401,"<"&TODAY())) | G13: =IF(A13="","",COUNTIFS(Lançamentos!$E$2:$E$401,A13,Lançamentos!$G$2:$G$401,"<>Concluído",Lançamentos!$F$2:$F$401,">="&TODAY(),Lançamentos!$F$2:$F$401,"<="&TODAY()+3)) | H13: =IF(A13="","",IF(F13>0,"🔴 COBRAR hoje",IF(G13>0,"🟠 Lembrar esta semana","🟢 Em dia")))
E14: =IF(A14="","",COUNTIFS(Lançamentos!$E$2:$E$401,A14,Lançamentos!$G$2:$G$401,"<>Concluído")) | F14: =IF(A14="","",COUNTIFS(Lançamentos!$E$2:$E$401,A14,Lançamentos!$G$2:$G$401,"<>Concluído",Lançamentos!$F$2:$F$401,"<"&TODAY())) | G14: =IF(A14="","",COUNTIFS(Lançamentos!$E$2:$E$401,A14,Lançamentos!$G$2:$G$401,"<>Concluído",Lançamentos!$F$2:$F$401,">="&TODAY(),Lançamentos!$F$2:$F$401,"<="&TODAY()+3)) | H14: =IF(A14="","",IF(F14>0,"🔴 COBRAR hoje",IF(G14>0,"🟠 Lembrar esta semana","🟢 Em dia")))
E15: =IF(A15="","",COUNTIFS(Lançamentos!$E$2:$E$401,A15,Lançamentos!$G$2:$G$401,"<>Concluído")) | F15: =IF(A15="","",COUNTIFS(Lançamentos!$E$2:$E$401,A15,Lançamentos!$G$2:$G$401,"<>Concluído",Lançamentos!$F$2:$F$401,"<"&TODAY())) | G15: =IF(A15="","",COUNTIFS(Lançamentos!$E$2:$E$401,A15,Lançamentos!$G$2:$G$401,"<>Concluído",Lançamentos!$F$2:$F$401,">="&TODAY(),Lançamentos!$F$2:$F$401,"<="&TODAY()+3)) | H15: =IF(A15="","",IF(F15>0,"🔴 COBRAR hoje",IF(G15>0,"🟠 Lembrar esta semana","🟢 Em dia")))
E16: =IF(A16="","",COUNTIFS(Lançamentos!$E$2:$E$401,A16,Lançamentos!$G$2:$G$401,"<>Concluído")) | F16: =IF(A16="","",COUNTIFS(Lançamentos!$E$2:$E$401,A16,Lançamentos!$G$2:$G$401,"<>Concluído",Lançamentos!$F$2:$F$401,"<"&TODAY())) | G16: =IF(A16="","",COUNTIFS(Lançamentos!$E$2:$E$401,A16,Lançamentos!$G$2:$G$401,"<>Concluído",Lançamentos!$F$2:$F$401,">="&TODAY(),Lançamentos!$F$2:$F$401,"<="&TODAY()+3)) | H16: =IF(A16="","",IF(F16>0,"🔴 COBRAR hoje",IF(G16>0,"🟠 Lembrar esta semana","🟢 Em dia")))
E17: =IF(A17="","",COUNTIFS(Lançamentos!$E$2:$E$401,A17,Lançamentos!$G$2:$G$401,"<>Concluído")) | F17: =IF(A17="","",COUNTIFS(Lançamentos!$E$2:$E$401,A17,Lançamentos!$G$2:$G$401,"<>Concluído",Lançamentos!$F$2:$F$401,"<"&TODAY())) | G17: =IF(A17="","",COUNTIFS(Lançamentos!$E$2:$E$401,A17,Lançamentos!$G$2:$G$401,"<>Concluído",Lançamentos!$F$2:$F$401,">="&TODAY(),Lançamentos!$F$2:$F$401,"<="&TODAY()+3)) | H17: =IF(A17="","",IF(F17>0,"🔴 COBRAR hoje",IF(G17>0,"🟠 Lembrar esta semana","🟢 Em dia")))
E18: =IF(A18="","",COUNTIFS(Lançamentos!$E$2:$E$401,A18,Lançamentos!$G$2:$G$401,"<>Concluído")) | F18: =IF(A18="","",COUNTIFS(Lançamentos!$E$2:$E$401,A18,Lançamentos!$G$2:$G$401,"<>Concluído",Lançamentos!$F$2:$F$401,"<"&TODAY())) | G18: =IF(A18="","",COUNTIFS(Lançamentos!$E$2:$E$401,A18,Lançamentos!$G$2:$G$401,"<>Concluído",Lançamentos!$F$2:$F$401,">="&TODAY(),Lançamentos!$F$2:$F$401,"<="&TODAY()+3)) | H18: =IF(A18="","",IF(F18>0,"🔴 COBRAR hoje",IF(G18>0,"🟠 Lembrar esta semana","🟢 Em dia")))
E19: =IF(A19="","",COUNTIFS(Lançamentos!$E$2:$E$401,A19,Lançamentos!$G$2:$G$401,"<>Concluído")) | F19: =IF(A19="","",COUNTIFS(Lançamentos!$E$2:$E$401,A19,Lançamentos!$G$2:$G$401,"<>Concluído",Lançamentos!$F$2:$F$401,"<"&TODAY())) | G19: =IF(A19="","",COUNTIFS(Lançamentos!$E$2:$E$401,A19,Lançamentos!$G$2:$G$401,"<>Concluído",Lançamentos!$F$2:$F$401,">="&TODAY(),Lançamentos!$F$2:$F$401,"<="&TODAY()+3)) | H19: =IF(A19="","",IF(F19>0,"🔴 COBRAR hoje",IF(G19>0,"🟠 Lembrar esta semana","🟢 Em dia")))
E20: =IF(A20="","",COUNTIFS(Lançamentos!$E$2:$E$401,A20,Lançamentos!$G$2:$G$401,"<>Concluído")) | F20: =IF(A20="","",COUNTIFS(Lançamentos!$E$2:$E$401,A20,Lançamentos!$G$2:$G$401,"<>Concluído",Lançamentos!$F$2:$F$401,"<"&TODAY())) | G20: =IF(A20="","",COUNTIFS(Lançamentos!$E$2:$E$401,A20,Lançamentos!$G$2:$G$401,"<>Concluído",Lançamentos!$F$2:$F$401,">="&TODAY(),Lançamentos!$F$2:$F$401,"<="&TODAY()+3)) | H20: =IF(A20="","",IF(F20>0,"🔴 COBRAR hoje",IF(G20>0,"🟠 Lembrar esta semana","🟢 Em dia")))
E21: =IF(A21="","",COUNTIFS(Lançamentos!$E$2:$E$401,A21,Lançamentos!$G$2:$G$401,"<>Concluído")) | F21: =IF(A21="","",COUNTIFS(Lançamentos!$E$2:$E$401,A21,Lançamentos!$G$2:$G$401,"<>Concluído",Lançamentos!$F$2:$F$401,"<"&TODAY())) | G21: =IF(A21="","",COUNTIFS(Lançamentos!$E$2:$E$401,A21,Lançamentos!$G$2:$G$401,"<>Concluído",Lançamentos!$F$2:$F$401,">="&TODAY(),Lançamentos!$F$2:$F$401,"<="&TODAY()+3)) | H21: =IF(A21="","",IF(F21>0,"🔴 COBRAR hoje",IF(G21>0,"🟠 Lembrar esta semana","🟢 Em dia")))
... E24: =IF(A24="","",COUNTIFS(Lançamentos!$E$2:$E$401,A24,Lançamentos!$G$2:$G$401,"<>Concluído")) | F24: =IF(A24="","",COUNTIFS(Lançamentos!$E$2:$E$401,A24,Lançamentos!$G$2:$G$401,"<>Concluído",Lançamentos!$F$2:$F$401,"<"&TODAY())) | G24: =IF(A24="","",COUNTIFS(Lançamentos!$E$2:$E$401,A24,Lançamentos!$G$2:$G$401,"<>Concluído",Lançamentos!$F$2:$F$401,">="&TODAY(),Lançamentos!$F$2:$F$401,"<="&TODAY()+3)) | H24: =IF(A24="","",IF(F24>0,"🔴 COBRAR hoje",IF(G24>0,"🟠 Lembrar esta semana","🟢 Em dia")))

Sheet Listas
A1: Listas de apoio
A2: Edite aqui as etapas padrão do Plano Propulse e quantos dias antes do lançamento cada uma deve estar pronta.
A4: Etapa do lançamento | B4: Dias antes do lançamento | D4: Status da tarefa | F4: Status do artista
A5: Briefing / planejamento | B5: 30 | D5: Não iniciado | F5: Ativo
A6: Capa / arte | B6: 21 | D6: Em andamento | F6: Pausado
A7: Upload na distribuidora | B7: 14 | D7: Aguardando artista | F7: Encerrado
A8: Pitch editorial Spotify | B8: 10 | D8: Concluído
A9: Pré-save | B9: 10
A10: Release / assessoria | B10: 7
A11: Conteúdo para redes (teasers) | B11: 7
A12: Visualizer / clipe | B12: 3
A13: Campanha de tráfego (Ads) | B13: 0
A14: Relatório pós-lançamento | B14: -14
A17: Dica: número negativo = depois do lançamento (ex.: -14 = relatório 14 dias após sair). Pitch no Spotify precisa ser enviado com pelo menos 7 dias de antecedência.

Sheet Como usar
B1: Como usar esta planilha
B3: Legenda de cores
B4: ■ Célula AMARELA com texto azul = você preenche. ■ Célula CINZA = fórmula, não precisa mexer.
B5: ■ Linha VERMELHA = tarefa atrasada → COBRAR o responsável. ■ Linha AMARELA = vence em até 3 dias → lembrar. ■ Texto cinza claro = concluído.
B7: Passo a passo
B8: 1. Aba Responsáveis: cadastre a equipe que executa os lançamentos (nome, função, WhatsApp, e-mail).
B9: 2. Aba Artistas: cadastre cada artista do Plano Propulse, com data de entrada e status (Ativo / Pausado / Encerrado).
B10: 3. Aba Lançamentos: para cada lançamento, crie uma linha por etapa (capa, upload, pitch, pré-save, ads...). Escolha artista, etapa, responsável e status nas listas.
B11: O PRAZO é calculado sozinho a partir da data de lançamento e da aba Listas. Se precisar de outro prazo, é só digitar a data por cima.
B12: 4. Atualize o STATUS conforme a equipe avança. Quando cobrar alguém, anote a data em 'Última cobrança'.
B13: 5. Abra a aba Painel todo dia: o bloco 'QUEM COBRAR' mostra exatamente quem cobrar, de qual artista e qual etapa.
B15: Dicas
... B18: • Funciona no Excel e no Google Sheets (Arquivo → Importar). No Google Sheets, você pode compartilhar com a equipe.
